Workbook
Name Slicer_Product: #N/A
Name Slicer_Salesperson: #N/A

Sheet Sales Data
A1: Order ID | B1: Order Date | C1: Region | D1: Salesperson | E1: Product | F1: Category | G1: Quantity | H1: Unit Price | I1: Sales Amount | J1: Cost | K1: Profit
A2: ORD1001 | B2: 46186 | C2: North | D2: Ananya | E2: Monitor | F2: Electronics | G2: 1 | H2: 18870 | I2: 18870 | J2: 12810 | K2: 6060
A3: ORD1002 | B3: 46049 | C3: South | D3: Priya | E3: Tablet | F3: Electronics | G3: 2 | H3: 28510 | I3: 57020 | J3: 35790 | K3: 21230
A4: ORD1003 | B4: 46082 | C4: West | D4: Priya | E4: Tablet | F4: Electronics | G4: 1 | H4: 28340 | I4: 28340 | J4: 22440 | K4: 5900
A5: ORD1004 | B5: 46137 | C5: North | D5: Ananya | E5: Webcam | F5: Accessories | G5: 5 | H5: 4780 | I5: 23900 | J5: 14860 | K5: 9040
A6: ORD1005 | B6: 46131 | C6: East | D6: Aarav | E6: Headset | F6: Accessories | G6: 5 | H6: 3260 | I6: 16300 | J6: 13850 | K6: 2450
A7: ORD1006 | B7: 46046 | C7: East | D7: Aarav | E7: Office Chair | F7: Furniture | G7: 2 | H7: 11660 | I7: 23320 | J7: 16380 | K7: 6940
A8: ORD1007 | B8: 46209 | C8: East | D8: Ananya | E8: Desk | F8: Furniture | G8: 2 | H8: 17510 | I8: 35020 | J8: 24890 | K8: 10130
A9: ORD1008 | B9: 46181 | C9: North | D9: Rahul | E9: Headset | F9: Accessories | G9: 4 | H9: 3640 | I9: 14560 | J9: 9190 | K9: 5370
A10: ORD1009 | B10: 46043 | C10: East | D10: Priya | E10: Mouse | F10: Accessories | G10: 2 | H10: 1170 | I10: 2340 | J10: 1710 | K10: 630
A11: ORD1010 | B11: 46117 | C11: South | D11: Vikram | E11: Headset | F11: Accessories | G11: 4 | H11: 3620 | I11: 14480 | J11: 11420 | K11: 3060
A12: ORD1011 | B12: 46185 | C12: North | D12: Ananya | E12: Keyboard | F12: Accessories | G12: 4 | H12: 2330 | I12: 9320 | J12: 6630 | K12: 2690
A13: ORD1012 | B13: 46106 | C13: West | D13: Rahul | E13: Laptop | F13: Electronics | G13: 4 | H13: 47900 | I13: 191600 | J13: 155810 | K13: 35790
... A301: ORD1300 | B301: 46096 | C301: South | D301: Priya | E301: Laptop | F301: Electronics | G301: 2 | H301: 46370 | I301: 92740 | J301: 62670 | K301: 30070

Sheet Project Guide
A1: Project Step | B1: Task
A2: 1. Data Preparation | B2: Check duplicates, blanks, date format, and convert the data to an Excel Table.
A3: 2. Basic Analysis | B3: Calculate total sales, cost, profit, quantity, and average order value.
A4: 3. PivotTables | B4: Analyze sales/profit by region, product, category, salesperson, and month.
A5: 4. Charts | B5: Create monthly sales trend, regional sales, top products, and category profit charts.
A6: 5. Dashboard | B6: Build a one-page dashboard with KPIs, PivotTables, and charts.
A7: 6. Business Insights | B7: Write 5–7 business insights based on your analysis.

Sheet Analysis
B2: 1. Create KPI Calculations
C4: SALES ANALYSIS | D4: Total Sales | E4: Total Cost | F4: Total Profit | G4: Total Quantity | H4: Average Sales | I4: Number of Orders
D5: =SUM('Sales Data'!I2:I301) -> 18625770 | E5: =SUM('Sales Data'!J2:J301) -> 13948200 | F5: =SUM('Sales Data'!K2:K301) -> 4677570 | G5: =SUM('Sales Data'!G2:G301) -> 1346 | H5: =AVERAGE('Sales Data'!I2:I301) -> 62085.9 | I5: =COUNTA('Sales Data'!A2:A301) -> 300
B8: 2. Analyze Sales by Region
C9: Region | D9: South | E9: North | F9: East | G9: West
C10: Total Sales | D10: =SUMIF('Sales Data'!$C:$C,D9,'Sales Data'!$K:$K) -> 1202660 | E10: =SUMIF('Sales Data'!$C:$C,E9,'Sales Data'!$K:$K) -> 727530 | F10: =SUMIF('Sales Data'!$C:$C,F9,'Sales Data'!$K:$K) -> 1260710 | G10: =SUMIF('Sales Data'!$C:$C,G9,'Sales Data'!$K:$K) -> 1486670
C12: Best Region | D12: =INDEX(D9:G9,MATCH(MAX(D10:G10),D10:G10,0)) -> West
C13: Highest Sales | D13: =MAX(D10:G10) -> 1486670
B16: 3. Analyze Products
C17: Product | D17: Total Sales
C18: Laptop | D18: =SUMIF('Sales Data'!$E:$E,C18,'Sales Data'!$I:$I) -> 4065840
C19: Monitor | D19: =SUMIF('Sales Data'!$E:$E,C19,'Sales Data'!$I:$I) -> 2908430
C20: Keyboard | D20: =SUMIF('Sales Data'!$E:$E,C20,'Sales Data'!$I:$I) -> 397200
C21: Mouse | D21: =SUMIF('Sales Data'!$E:$E,C21,'Sales Data'!$I:$I) -> 163860
C22: Printer | D22: =SUMIF('Sales Data'!$E:$E,C22,'Sales Data'!$I:$I) -> 2126380
C23: Headset | D23: =SUMIF('Sales Data'!$E:$E,C23,'Sales Data'!$I:$I) -> 403070
C24: Office Chair | D24: =SUMIF('Sales Data'!$E:$E,C24,'Sales Data'!$I:$I) -> 1398220
C25: Desk | D25: =SUMIF('Sales Data'!$E:$E,C25,'Sales Data'!$I:$I) -> 2765060
C26: Tablet | D26: =SUMIF('Sales Data'!$E:$E,C26,'Sales Data'!$I:$I) -> 3900840
C27: Webcam | D27: =SUMIF('Sales Data'!$E:$E,C27,'Sales Data'!$I:$I) -> 496870
B29: 3a. Find the Top Product
C30: Top Product | D30: =INDEX(C18:C27,MATCH(MAX(D18:D27),D18:D27,0)) -> Laptop
C31: highest product sales: | D31: =MAX(D18:D27) -> 4065840

Sheet Pivot Table
A2: 1. Region Analysis
A3: Row Labels | B3: Sum of Sales Amount
A4: East | B4: 700120
A5: North | B5: 272350
A6: South | B6: 337300
A7: West | B7: 1269920
A8: Grand Total | B8: 2579690
A16: 2. Monthly Sales Analysis
A17: Row Labels | B17: Sum of Sales Amount
A18: Jan | B18: 2869930
A19: Feb | B19: 1992680
A20: Mar | B20: 2162990
A21: Apr | B21: 3546870
A22: May | B22: 2318910
A23: Jun | B23: 2740140
A24: Jul | B24: 2994250
A25: Grand Total | B25: 18625770
A27: Which month had the highest sales?
A28: =MAX(B18:B24) -> 3546870
A29: =INDEX(A18:A24,MATCH(MAX(B18:B24),B18:B24,0)) -> Apr
A32: 2. Product Sales PivotTable
A33: Row Labels | B33: Sum of Sales Amount
A34: Desk | B34: 2765060
A35: Laptop | B35: 4065840
A36: Monitor | B36: 2908430
A37: Printer | B37: 2126380
A38: Tablet | B38: 3900840
A39: Grand Total | B39: 15766550
A48: 4. Salesperson Performance
A49: Row Labels | B49: Sum of Sales Amount | C49: Sum of Profit
A50: Aarav | B50: 2579690 | C50: 652600
A51: Ananya | B51: 2889340 | C51: 726470
A52: Priya | B52: 2728780 | C52: 747520
A53: Rahul | B53: 3774800 | C53: 941220
A54: Sneha | B54: 2340840 | C54: 561590
A55: Vikram | B55: 4312320 | C55: 1048170
A56: Grand Total | B56: 18625770 | C56: 4677570
A60: Row Labels | B60: Sum of Profit
A61: Accessories | B61: 386070
A62: Electronics | B62: 3256100
...

Sheet Analysis Report
A1: SALES ANALYSIS | B1: Total Sales | C1: Total Cost | D1: Total Profit | E1: Total Quantity | F1: Average Sales | G1: Number of Orders
B2: 18625770 | C2: 13948200 | D2: 4677570 | E2: 1346 | F2: 62085.9 | G2: 300
